<?xml version="1.0" ?>
<!-- =================================================================================== -->
<!-- |    This document was autogenerated by xacro from /home/jakub/Repos/sPrinter/ROS_ws/src/sprinter_description/urdf/sPrinter.xacro | -->
<!-- |    EDITING THIS FILE BY HAND IS NOT RECOMMENDED                                 | -->
<!-- =================================================================================== -->
<robot name="sPrinter">
    <material name="silver">
        <color rgba="0.700 0.700 0.700 1.000" />
    </material>
    <transmission name="Boggie_right_tran">
        <type>transmission_interface/SimpleTransmission</type>
        <joint name="Boggie_right">
            <hardwareInterface>hardware_interface/EffortJointInterface</hardwareInterface>
        </joint>
        <actuator name="Boggie_right_actr">
            <hardwareInterface>hardware_interface/EffortJointInterface</hardwareInterface>
            <mechanicalReduction>1</mechanicalReduction>
        </actuator>
    </transmission>
    <transmission name="Boggie_left_tran">
        <type>transmission_interface/SimpleTransmission</type>
        <joint name="Boggie_left">
            <hardwareInterface>hardware_interface/EffortJointInterface</hardwareInterface>
        </joint>
        <actuator name="Boggie_left_actr">
            <hardwareInterface>hardware_interface/EffortJointInterface</hardwareInterface>
            <mechanicalReduction>1</mechanicalReduction>
        </actuator>
    </transmission>
    <transmission name="Wheel_right_front_tran">
        <type>transmission_interface/SimpleTransmission</type>
        <joint name="Wheel_right_front">
            <hardwareInterface>hardware_interface/VelocityJointInterface</hardwareInterface>
        </joint>
        <actuator name="Wheel_right_front_actr">
            <hardwareInterface>hardware_interface/VelocityJointInterface</hardwareInterface>
            <mechanicalReduction>1</mechanicalReduction>
        </actuator>
    </transmission>
    <transmission name="Wheel_right_middle_tran">
        <type>transmission_interface/SimpleTransmission</type>
        <joint name="Wheel_right_middle">
            <hardwareInterface>hardware_interface/VelocityJointInterface</hardwareInterface>
        </joint>
        <actuator name="Wheel_right_middle_actr">
            <hardwareInterface>hardware_interface/VelocityJointInterface</hardwareInterface>
            <mechanicalReduction>1</mechanicalReduction>
        </actuator>
    </transmission>
    <transmission name="Wheel_right_rear_tran">
        <type>transmission_interface/SimpleTransmission</type>
        <joint name="Wheel_right_rear">
            <hardwareInterface>hardware_interface/VelocityJointInterface</hardwareInterface>
        </joint>
        <actuator name="Wheel_right_rear_actr">
            <hardwareInterface>hardware_interface/VelocityJointInterface</hardwareInterface>
            <mechanicalReduction>1</mechanicalReduction>
        </actuator>
    </transmission>
    <transmission name="Wheel_left_front_tran">
        <type>transmission_interface/SimpleTransmission</type>
        <joint name="Wheel_left_front">
            <hardwareInterface>hardware_interface/VelocityJointInterface</hardwareInterface>
        </joint>
        <actuator name="Wheel_left_front_actr">
            <hardwareInterface>hardware_interface/VelocityJointInterface</hardwareInterface>
            <mechanicalReduction>1</mechanicalReduction>
        </actuator>
    </transmission>
    <transmission name="Wheel_left_middle_tran">
        <type>transmission_interface/SimpleTransmission</type>
        <joint name="Wheel_left_middle">
            <hardwareInterface>hardware_interface/VelocityJointInterface</hardwareInterface>
        </joint>
        <actuator name="Wheel_left_middle_actr">
            <hardwareInterface>hardware_interface/VelocityJointInterface</hardwareInterface>
            <mechanicalReduction>1</mechanicalReduction>
        </actuator>
    </transmission>
    <transmission name="Wheel_left_rear_tran">
        <type>transmission_interface/SimpleTransmission</type>
        <joint name="Wheel_left_rear">
            <hardwareInterface>hardware_interface/VelocityJointInterface</hardwareInterface>
        </joint>
        <actuator name="Wheel_left_rear_actr">
            <hardwareInterface>hardware_interface/VelocityJointInterface</hardwareInterface>
            <mechanicalReduction>1</mechanicalReduction>
        </actuator>
    </transmission>
    <transmission name="MainFrame_pitch_tran">
        <type>transmission_interface/SimpleTransmission</type>
        <joint name="MainFrame_pitch">
            <hardwareInterface>hardware_interface/EffortJointInterface</hardwareInterface>
        </joint>
        <actuator name="MainFrame_pitch_actr">
            <hardwareInterface>hardware_interface/EffortJointInterface</hardwareInterface>
            <mechanicalReduction>1</mechanicalReduction>
        </actuator>
    </transmission>
    <transmission name="Lens_Y_axis_trans_tran">
        <type>transmission_interface/SimpleTransmission</type>
        <joint name="Lens_Y_axis_trans">
            <hardwareInterface>hardware_interface/EffortJointInterface</hardwareInterface>
        </joint>
        <actuator name="Lens_Y_axis_trans_actr">
            <hardwareInterface>hardware_interface/EffortJointInterface</hardwareInterface>
            <mechanicalReduction>1</mechanicalReduction>
        </actuator>
    </transmission>
    <transmission name="Lens_X_axis_trans_tran">
        <type>transmission_interface/SimpleTransmission</type>
        <joint name="Lens_X_axis_trans">
            <hardwareInterface>hardware_interface/EffortJointInterface</hardwareInterface>
        </joint>
        <actuator name="Lens_X_axis_trans_actr">
            <hardwareInterface>hardware_interface/EffortJointInterface</hardwareInterface>
            <mechanicalReduction>1</mechanicalReduction>
        </actuator>
    </transmission>
    <transmission name="Lens_Y_axis_rot_tran">
        <type>transmission_interface/SimpleTransmission</type>
        <joint name="Lens_Y_axis_rot">
            <hardwareInterface>hardware_interface/EffortJointInterface</hardwareInterface>
        </joint>
        <actuator name="Lens_Y_axis_rot_actr">
            <hardwareInterface>hardware_interface/EffortJointInterface</hardwareInterface>
            <mechanicalReduction>1</mechanicalReduction>
        </actuator>
    </transmission>
    <transmission name="Lens_X_axis_rot_tran">
        <type>transmission_interface/SimpleTransmission</type>
        <joint name="Lens_X_axis_rot">
            <hardwareInterface>hardware_interface/EffortJointInterface</hardwareInterface>
        </joint>
        <actuator name="Lens_X_axis_rot_actr">
            <hardwareInterface>hardware_interface/EffortJointInterface</hardwareInterface>
            <mechanicalReduction>1</mechanicalReduction>
        </actuator>
    </transmission>
    <gazebo>
        <plugin filename="libgazebo_ros_control.so" name="control" />
        <plugin name="gazebo_ros_control">
            <robotNamespace>/</robotNamespace>
        </plugin>
    </gazebo>
    <gazebo reference="dummy_link">
        <material>Gazebo/Silver</material>
        <mu1>0.2</mu1>
        <mu2>0.2</mu2>
        <selfCollide>false</selfCollide>
        <gravity>false</gravity>
    </gazebo>
    <gazebo reference="base_link">
        <material>Gazebo/Silver</material>
        <mu1>0.2</mu1>
        <mu2>0.2</mu2>
        <selfCollide>true</selfCollide>
        <gravity>true</gravity>
    </gazebo>
    <gazebo reference="boggie_right_link">
        <material>Gazebo/Silver</material>
        <mu1>0.2</mu1>
        <mu2>0.2</mu2>
        <selfCollide>true</selfCollide>
    </gazebo>
    <gazebo reference="boggie_left_link">
        <material>Gazebo/Silver</material>
        <mu1>0.2</mu1>
        <mu2>0.2</mu2>
        <selfCollide>true</selfCollide>
    </gazebo>
    <gazebo reference="wheel_right_front_link">
        <material>Gazebo/Silver</material>
        <mu1>0.2</mu1>
        <mu2>0.2</mu2>
        <selfCollide>true</selfCollide>
    </gazebo>
    <gazebo reference="wheel_right_middle_link">
        <material>Gazebo/Silver</material>
        <mu1>0.2</mu1>
        <mu2>0.2</mu2>
        <selfCollide>true</selfCollide>
    </gazebo>
    <gazebo reference="wheel_right_rear_link">
        <material>Gazebo/Silver</material>
        <mu1>0.2</mu1>
        <mu2>0.2</mu2>
        <selfCollide>true</selfCollide>
    </gazebo>
    <gazebo reference="wheel_left_front_link">
        <material>Gazebo/Silver</material>
        <mu1>0.2</mu1>
        <mu2>0.2</mu2>
        <selfCollide>true</selfCollide>
    </gazebo>
    <gazebo reference="wheel_left_middle_link">
        <material>Gazebo/Silver</material>
        <mu1>0.2</mu1>
        <mu2>0.2</mu2>
        <selfCollide>true</selfCollide>
    </gazebo>
    <gazebo reference="wheel_left_rear_link">
        <material>Gazebo/Silver</material>
        <mu1>0.2</mu1>
        <mu2>0.2</mu2>
        <selfCollide>true</selfCollide>
    </gazebo>
    <gazebo reference="body_link">
        <material>Gazebo/Silver</material>
        <mu1>0.2</mu1>
        <mu2>0.2</mu2>
        <selfCollide>true</selfCollide>
    </gazebo>
    <gazebo reference="lens_Ylin_link">
        <material>Gazebo/Silver</material>
        <mu1>0.2</mu1>
        <mu2>0.2</mu2>
        <selfCollide>true</selfCollide>
    </gazebo>
    <gazebo reference="lens_Xlin_link">
        <material>Gazebo/Silver</material>
        <mu1>0.2</mu1>
        <mu2>0.2</mu2>
        <selfCollide>true</selfCollide>
    </gazebo>
    <gazebo reference="lens_Yrot_link">
        <material>Gazebo/Silver</material>
        <mu1>0.2</mu1>
        <mu2>0.2</mu2>
        <selfCollide>true</selfCollide>
    </gazebo>
    <gazebo reference="lens_Xrot_link">
        <material>Gazebo/Silver</material>
        <mu1>0.2</mu1>
        <mu2>0.2</mu2>
        <selfCollide>true</selfCollide>
    </gazebo>
    <!--  LINKS  ......................................................................................................-->
    <link name="dummy_link" />
    <link name="base_link">
        <inertial>
            <origin rpy="0 0 0" xyz="0.17638918566028436 -1.1617803251776711e-10 0.20039906221891166" />
            <mass value="17.932039150286514" />
            <inertia ixx="1.269299" ixy="-0.000127" ixz="0.306923" iyy="1.199687" iyz="-0.0" izz="2.152463" />
        </inertial>
        <visual>
            <origin rpy="0 0 0" xyz="0 0 0" />
            <geometry>
                <mesh filename="package://sprinter_description/meshes/base_link.stl" scale="0.001 0.001 0.001" />
            </geometry>
            <material name="silver" />
        </visual>
        <collision>
            <origin rpy="0 0 0" xyz="0 0 0" />
            <geometry>
                <mesh filename="package://sprinter_description/meshes/base_link.stl" scale="0.001 0.001 0.001" />
            </geometry>
        </collision>
    </link>
    <link name="boggie_right">
        <inertial>
            <origin rpy="0 0 0" xyz="0.04608835670723324 -0.05868381694977415 -0.08782934708885383" />
            <mass value="9.260994382343632" />
            <inertia ixx="0.043816" ixy="0.001419" ixz="0.005147" iyy="0.34178" iyz="-0.011146" izz="0.334085" />
        </inertial>
        <visual>
            <origin rpy="0 0 0" xyz="0.26 0.22975 -0.21" />
            <geometry>
                <mesh filename="package://sprinter_description/meshes/boggie_right.stl" scale="0.001 0.001 0.001" />
            </geometry>
            <material name="silver" />
        </visual>
        <collision>
            <origin rpy="0 0 0" xyz="0.26 0.22975 -0.21" />
            <geometry>
                <mesh filename="package://sprinter_description/meshes/boggie_right.stl" scale="0.001 0.001 0.001" />
            </geometry>
        </collision>
    </link>
    <link name="boggie_left">
        <inertial>
            <origin rpy="0 0 0" xyz="0.04608852267144553 0.05868381722034843 -0.0878295588540255" />
            <mass value="9.26099437267114" />
            <inertia ixx="0.043816" ixy="-0.001419" ixz="0.005146" iyy="0.34178" iyz="0.011146" izz="0.334085" />
        </inertial>
        <visual>
            <origin rpy="0 0 0" xyz="0.26 -0.22975 -0.21" />
            <geometry>
                <mesh filename="package://sprinter_description/meshes/boggie_left.stl" scale="0.001 0.001 0.001" />
            </geometry>
            <material name="silver" />
        </visual>
        <collision>
            <origin rpy="0 0 0" xyz="0.26 -0.22975 -0.21" />
            <geometry>
                <mesh filename="package://sprinter_description/meshes/boggie_left.stl" scale="0.001 0.001 0.001" />
            </geometry>
        </collision>
    </link>
    <link name="wheel_right_front">
        <inertial>
            <origin rpy="0 0 0" xyz="-2.2157215140428121e-07 0.049038331285879255 -5.319570878098423e-07" />
            <mass value="16.784680388840883" />
            <inertia ixx="0.065217" ixy="-0.0" ixz="-0.0" iyy="0.075835" iyz="-0.0" izz="0.065217" />
        </inertial>
        <visual>
            <origin rpy="0 0 0" xyz="-0.42 0.38275 -0.09" />
            <geometry>
                <mesh filename="package://sprinter_description/meshes/wheel_right_front.stl" scale="0.001 0.001 0.001" />
            </geometry>
            <material name="silver" />
        </visual>
        <collision>
            <origin rpy="0 0 0" xyz="-0.42 0.38275 -0.09" />
            <geometry>
                <mesh filename="package://sprinter_description/meshes/wheel_right_front.stl" scale="0.001 0.001 0.001" />
            </geometry>
        </collision>
    </link>
    <link name="wheel_right_middle">
        <inertial>
            <origin rpy="0 0 0" xyz="-2.441464656044445e-07 0.049038331285878034 -1.2471173249650747e-07" />
            <mass value="16.784680388841224" />
            <inertia ixx="0.065217" ixy="-0.0" ixz="-0.0" iyy="0.075835" iyz="-0.0" izz="0.065217" />
        </inertial>
        <visual>
            <origin rpy="0 0 0" xyz="0.0 0.40375 -0.09" />
            <geometry>
                <mesh filename="package://sprinter_description/meshes/wheel_right_middle.stl" scale="0.001 0.001 0.001" />
            </geometry>
            <material name="silver" />
        </visual>
        <collision>
            <origin rpy="0 0 0" xyz="0.0 0.40375 -0.09" />
            <geometry>
                <mesh filename="package://sprinter_description/meshes/wheel_right_middle.stl" scale="0.001 0.001 0.001" />
            </geometry>
        </collision>
    </link>
    <link name="wheel_right_rear">
        <inertial>
            <origin rpy="0 0 0" xyz="-2.4414526850202733e-07 0.04903833128586854 4.1045225383784523e-07" />
            <mass value="16.78468038884136" />
            <inertia ixx="0.065217" ixy="-0.0" ixz="-0.0" iyy="0.075835" iyz="-0.0" izz="0.065217" />
        </inertial>
        <visual>
            <origin rpy="0 0 0" xyz="0.42 0.40375 -0.09" />
            <geometry>
                <mesh filename="package://sprinter_description/meshes/wheel_right_rear.stl" scale="0.001 0.001 0.001" />
            </geometry>
            <material name="silver" />
        </visual>
        <collision>
            <origin rpy="0 0 0" xyz="0.42 0.40375 -0.09" />
            <geometry>
                <mesh filename="package://sprinter_description/meshes/wheel_right_rear.stl" scale="0.001 0.001 0.001" />
            </geometry>
        </collision>
    </link>
    <link name="wheel_left_front">
        <inertial>
            <origin rpy="0 0 0" xyz="-1.7782965933133e-08 -0.04903833128669849 -7.65968576066367e-08" />
            <mass value="16.78468038884107" />
            <inertia ixx="0.065217" ixy="-0.0" ixz="0.0" iyy="0.075835" iyz="0.0" izz="0.065217" />
        </inertial>
        <visual>
            <origin rpy="0 0 0" xyz="-0.42 -0.38275 -0.09" />
            <geometry>
                <mesh filename="package://sprinter_description/meshes/wheel_left_front.stl" scale="0.001 0.001 0.001" />
            </geometry>
            <material name="silver" />
        </visual>
        <collision>
            <origin rpy="0 0 0" xyz="-0.42 -0.38275 -0.09" />
            <geometry>
                <mesh filename="package://sprinter_description/meshes/wheel_left_front.stl" scale="0.001 0.001 0.001" />
            </geometry>
        </collision>
    </link>
    <link name="wheel_left_middle">
        <inertial>
            <origin rpy="0 0 0" xyz="1.038819750736053e-06 -0.049038331286717474 0.00010982563519425226" />
            <mass value="16.784680388841238" />
            <inertia ixx="0.065217" ixy="-0.0" ixz="0.0" iyy="0.075835" iyz="0.0" izz="0.065217" />
        </inertial>
        <visual>
            <origin rpy="0 0 0" xyz="-0.0 -0.40375 -0.09" />
            <geometry>
                <mesh filename="package://sprinter_description/meshes/wheel_left_middle.stl" scale="0.001 0.001 0.001" />
            </geometry>
            <material name="silver" />
        </visual>
        <collision>
            <origin rpy="0 0 0" xyz="-0.0 -0.40375 -0.09" />
            <geometry>
                <mesh filename="package://sprinter_description/meshes/wheel_left_middle.stl" scale="0.001 0.001 0.001" />
            </geometry>
        </collision>
    </link>
    <link name="wheel_left_rear">
        <inertial>
            <origin rpy="0 0 0" xyz="1.0388197915767172e-06 -0.04903833128671531 0.00010972160107960982" />
            <mass value="16.7846803888409" />
            <inertia ixx="0.065217" ixy="-0.0" ixz="0.0" iyy="0.075835" iyz="0.0" izz="0.065217" />
        </inertial>
        <visual>
            <origin rpy="0 0 0" xyz="0.42 -0.40375 -0.09" />
            <geometry>
                <mesh filename="package://sprinter_description/meshes/wheel_left_rear.stl" scale="0.001 0.001 0.001" />
            </geometry>
            <material name="silver" />
        </visual>
        <collision>
            <origin rpy="0 0 0" xyz="0.42 -0.40375 -0.09" />
            <geometry>
                <mesh filename="package://sprinter_description/meshes/wheel_left_rear.stl" scale="0.001 0.001 0.001" />
            </geometry>
        </collision>
    </link>
    <link name="body">
        <inertial>
            <origin rpy="0 0 0" xyz="-0.08748571926603223 0.002858790568392067 -0.009190179413522459" />
            <mass value="37.61630562888167" />
            <inertia ixx="0.853323" ixy="-0.02383" ixz="-0.223821" iyy="1.507235" iyz="-0.017735" izz="1.939307" />
        </inertial>
        <visual>
            <origin rpy="0 0 0" xyz="0.0 0.0 -0.31" />
            <geometry>
                <mesh filename="package://sprinter_description/meshes/body.stl" scale="0.001 0.001 0.001" />
            </geometry>
            <material name="silver" />
        </visual>
        <collision>
            <origin rpy="0 0 0" xyz="0.0 0.0 -0.31" />
            <geometry>
                <mesh filename="package://sprinter_description/meshes/body.stl" scale="0.001 0.001 0.001" />
            </geometry>
        </collision>
    </link>
    <link name="lens_Ylin">
        <inertial>
            <origin rpy="0 0 0" xyz="-0.19050492237401995 0.01911574728140262 0.050354275554037764" />
            <mass value="8.115658394698128" />
            <inertia ixx="0.588454" ixy="0.014229" ixz="0.015923" iyy="0.584795" iyz="-0.000613" izz="1.16382" />
        </inertial>
        <visual>
            <origin rpy="0 0 0" xyz="-0.1445 0.020515 -0.453" />
            <geometry>
                <mesh filename="package://sprinter_description/meshes/lens_Ylin.stl" scale="0.001 0.001 0.001" />
            </geometry>
            <material name="silver" />
        </visual>
        <collision>
            <origin rpy="0 0 0" xyz="-0.1445 0.020515 -0.453" />
            <geometry>
                <mesh filename="package://sprinter_description/meshes/lens_Ylin.stl" scale="0.001 0.001 0.001" />
            </geometry>
        </collision>
    </link>
    <link name="lens_Xlin">
        <inertial>
            <origin rpy="0 0 0" xyz="0.23595566779369742 0.13671241587093597 0.03333844333172431" />
            <mass value="1.8074023885886255" />
            <inertia ixx="0.123515" ixy="-0.045751" ixz="-0.000589" iyy="0.081004" iyz="-0.000469" izz="0.20416" />
        </inertial>
        <visual>
            <origin rpy="0 0 0" xyz="0.2502 0.0 -0.49414" />
            <geometry>
                <mesh filename="package://sprinter_description/meshes/lens_Xlin.stl" scale="0.001 0.001 0.001" />
            </geometry>
            <material name="silver" />
        </visual>
        <collision>
            <origin rpy="0 0 0" xyz="0.2502 0.0 -0.49414" />
            <geometry>
                <mesh filename="package://sprinter_description/meshes/lens_Xlin.stl" scale="0.001 0.001 0.001" />
            </geometry>
        </collision>
    </link>
    <link name="lens_Yrot">
        <inertial>
            <origin rpy="0 0 0" xyz="0.15610000473558938 -0.28034931010215036 0.01290803779832872" />
            <mass value="1.6400641565943115" />
            <inertia ixx="0.034387" ixy="0.002102" ixz="-0.002749" iyy="0.070049" iyz="0.00012" izz="0.103823" />
        </inertial>
        <visual>
            <origin rpy="0 0 0" xyz="-0.144866 -0.270552 -0.528953" />
            <geometry>
                <mesh filename="package://sprinter_description/meshes/lens_Yrot.stl" scale="0.001 0.001 0.001" />
            </geometry>
            <material name="silver" />
        </visual>
        <collision>
            <origin rpy="0 0 0" xyz="-0.144866 -0.270552 -0.528953" />
            <geometry>
                <mesh filename="package://sprinter_description/meshes/lens_Yrot.stl" scale="0.001 0.001 0.001" />
            </geometry>
        </collision>
    </link>
    <link name="lens_Xrot">
        <inertial>
            <origin rpy="0 0 0" xyz="-0.2533217422271652 7.584721687383723e-06 0.0013476837862036462" />
            <mass value="6.552542872975625" />
            <inertia ixx="0.149538" ixy="0.0" ixz="2e-06" iyy="0.149827" iyz="0.000816" izz="0.299329" />
        </inertial>
        <visual>
            <origin rpy="0 0 0" xyz="-0.392366 8.1e-05 -0.552581" />
            <geometry>
                <mesh filename="package://sprinter_description/meshes/lens_Xrot.stl" scale="0.001 0.001 0.001" />
            </geometry>
            <material name="silver" />
        </visual>
        <collision>
            <origin rpy="0 0 0" xyz="-0.392366 8.1e-05 -0.552581" />
            <geometry>
                <mesh filename="package://sprinter_description/meshes/lens_Xrot.stl" scale="0.001 0.001 0.001" />
            </geometry>
        </collision>
    </link>
    <!--  frame in the middle of the lens-->
    <link name="lens_middle">
        <inertial>
            <origin rpy="0 0 0" xyz="0.0 0.0 0.0" />
            <mass value="0.0" />
            <inertia ixx="0.0" ixy="0.0" ixz="0.0" iyy="0.0" iyz="0.0" izz="0.0" />
        </inertial>
    </link>
    <link name="lens_focal">
        <inertial>
            <origin rpy="0 0 0" xyz="0.0 0.0 0.0" />
            <mass value="0.0" />
            <inertia ixx="0.0" ixy="0.0" ixz="0.0" iyy="0.0" iyz="0.0" izz="0.0" />
        </inertial>
    </link>
    <link name="ref_print_space">
        <inertial>
            <origin rpy="0 0 0" xyz="0.0 0.0 0.0" />
            <mass value="0.0" />
            <inertia ixx="0.0" ixy="0.0" ixz="0.0" iyy="0.0" iyz="0.0" izz="0.0" />
        </inertial>
    </link>
    <!--  JOINTS  .......................................................................................................-->
    <!--dummy-->
    <joint name="dummy_joint" type="fixed">
        <origin rpy="0 0 0" xyz="0.0 0.0 0.0" />
        <parent link="dummy_link" />
        <child link="base_link" />
    </joint>
    <joint name="Boggie_right" type="revolute">
        <origin rpy="0 0 0" xyz="-0.26 -0.22975 0.21" />
        <parent link="base_link" />
        <child link="boggie_right" />
        <axis xyz="-0.0 1.0 0.0" />
        <limit effort="100" lower="-0.523599" upper="0.523599" velocity="100" />
    </joint>
    <joint name="Boggie_left" type="revolute">
        <origin rpy="0 0 0" xyz="-0.26 0.22975 0.21" />
        <parent link="base_link" />
        <child link="boggie_left" />
        <axis xyz="0.0 1.0 0.0" />
        <limit effort="100" lower="-0.523599" upper="0.523599" velocity="100" />
    </joint>
    <joint name="Wheel_right_front" type="continuous">
        <origin rpy="0 0 0" xyz="0.42 -0.38275 0.09" />
        <parent link="base_link" />
        <child link="wheel_right_front" />
        <axis xyz="0.0 1.0 0.0" />
    </joint>
    <joint name="Wheel_right_middle" type="continuous">
        <origin rpy="0 0 0" xyz="0.26 -0.174 -0.12" />
        <parent link="boggie_right" />
        <child link="wheel_right_middle" />
        <axis xyz="0.0 1.0 0.0" />
    </joint>
    <joint name="Wheel_right_rear" type="continuous">
        <origin rpy="0 0 0" xyz="-0.16 -0.174 -0.12" />
        <parent link="boggie_right" />
        <child link="wheel_right_rear" />
        <axis xyz="0.0 1.0 0.0" />
    </joint>
    <joint name="Wheel_left_front" type="continuous">
        <origin rpy="0 0 0" xyz="0.42 0.38275 0.09" />
        <parent link="base_link" />
        <child link="wheel_left_front" />
        <axis xyz="0.0 1.0 0.0" />
    </joint>
    <joint name="Wheel_left_middle" type="continuous">
        <origin rpy="0 0 0" xyz="0.26 0.174 -0.12" />
        <parent link="boggie_left" />
        <child link="wheel_left_middle" />
        <axis xyz="0.0 1.0 0.0" />
    </joint>
    <joint name="Wheel_left_rear" type="continuous">
        <origin rpy="0 0 0" xyz="-0.16 0.174 -0.12" />
        <parent link="boggie_left" />
        <child link="wheel_left_rear" />
        <axis xyz="0.0 1.0 0.0" />
    </joint>
    <joint name="Body_pitch" type="revolute">
        <origin rpy="0 0 0" xyz="0.0 0.0 0.31" />
        <parent link="base_link" />
        <child link="body" />
        <axis xyz="-0.0 1.0 0.0" />
        <limit effort="100" lower="-0.523599" upper="0.523599" velocity="100" />
    </joint>
    <joint name="Lens_Y_axis_trans" type="prismatic">
        <origin rpy="0 0 0" xyz="0.1445 -0.020515 0.143" />
        <parent link="body" />
        <child link="lens_Ylin" />
        <axis xyz="0.0 1.0 0.0" />
        <limit effort="100" lower="-0.12" upper="0.15" velocity="100" />
    </joint>
    <joint name="Lens_X_axis_trans" type="prismatic">
        <origin rpy="0 0 0" xyz="-0.3947 0.020515 0.04114" />
        <parent link="lens_Ylin" />
        <child link="lens_Xlin" />
        <axis xyz="1.0 -0.0 0.0" />
        <limit effort="100" lower="0.0" upper="0.65" velocity="100" />
    </joint>
    <joint name="Lens_Y_axis_rot" type="revolute">
        <origin rpy="0 0 0" xyz="0.395066 0.270552 0.034813" />
        <parent link="lens_Xlin" />
        <child link="lens_Yrot" />
        <axis xyz="0.0 0.999999 0.001376" />
        <limit effort="100" lower="-0.698132" upper="0.698132" velocity="100" />
    </joint>
    <joint name="Lens_X_axis_rot" type="revolute">
        <origin rpy="0 0 0" xyz="0.2475 -0.270633 0.023628" />
        <parent link="lens_Yrot" />
        <child link="lens_Xrot" />
        <axis xyz="1.0 -0.0 0.0" />
        <limit effort="100" lower="-1.2" upper="1.2" velocity="100" />
    </joint>
    <!--middle frame joint-->
    <joint name="lens_middle_joint" type="fixed">
        <origin rpy="0 0 0" xyz="-0.2535  0.0 0.0" />
        <parent link="lens_Xrot" />
        <child link="lens_middle" />
    </joint>
    <!--focal work frame joint-->
    <joint name="lens_focal_joint" type="fixed">
        <origin rpy="0 0 0" xyz="0.0 0.0 -0.55" />
        <!-- z: ohniskova vzdialenost -->
        <parent link="lens_middle" />
        <child link="lens_focal" />
    </joint>
    <!--focal static frame joint-->
    <joint name="ref_print_space_joint" type="fixed">
        <origin rpy="0 0 0" xyz="0.753764 0.0 -0.0" />
        <!-- z: -55cm - ohniskova vzdialenost = 0cm nad rovinou zeme-->
        <!-- x: 0.753764 je pri 0.615m vysunuti sosovky v x (HOME) ... pod lens_middle frame-->
        <parent link="base_link" />
        <child link="ref_print_space" />
    </joint>
    <transmission name="trans_Body_pitch">
        <type>transmission_interface/SimpleTransmission</type>
        <joint name="Body_pitch">
            <hardwareInterface>hardware_interface/EffortJointInterface</hardwareInterface>
        </joint>
        <actuator name="Body_pitch_motor">
            <hardwareInterface>hardware_interface/EffortJointInterface</hardwareInterface>
            <mechanicalReduction>1</mechanicalReduction>
        </actuator>
    </transmission>
</robot>

