<?xml version="1.0" ?>
<robot name="sPrinter" xmlns:xacro="http://www.ros.org/wiki/xacro">

  <xacro:include filename="$(find sprinter_description)/urdf/materials.xacro" />
  <xacro:include filename="$(find sprinter_description)/urdf/sPrinter.trans" />
  <xacro:include filename="$(find sprinter_description)/urdf/sPrinter.gazebo" />

  <!--  LINKS  ......................................................................................................-->
  <link name="base_link">
    <inertial>
      <origin xyz="0.17638918566028436 -1.1617803251776711e-10 0.20039906221891166" rpy="0 0 0"/>
      <mass value="17.932039150286514"/>
      <inertia ixx="1.269299" iyy="1.199687" izz="2.152463" ixy="-0.000127" iyz="-0.0" ixz="0.306923"/>
    </inertial>
    <visual>
      <origin xyz="0 0 0" rpy="0 0 0"/>
      <geometry>
        <mesh filename="package://sprinter_description/meshes/base_link.stl" scale="0.001 0.001 0.001"/>
      </geometry>
      <material name="silver"/>
    </visual>
    <collision>
      <origin xyz="0 0 0" rpy="0 0 0"/>
      <geometry>
        <mesh filename="package://sprinter_description/meshes/base_link.stl" scale="0.001 0.001 0.001"/>
      </geometry>
    </collision>
  </link>

  <link name="boggie_right">
    <inertial>
      <origin xyz="0.04608835670723324 -0.05868381694977415 -0.08782934708885383" rpy="0 0 0"/>
      <mass value="9.260994382343632"/>
      <inertia ixx="0.043816" iyy="0.34178" izz="0.334085" ixy="0.001419" iyz="-0.011146" ixz="0.005147"/>
    </inertial>
    <visual>
      <origin xyz="0.26 0.22975 -0.21" rpy="0 0 0"/>
      <geometry>
        <mesh filename="package://sprinter_description/meshes/boggie_right.stl" scale="0.001 0.001 0.001"/>
      </geometry>
      <material name="silver"/>
    </visual>
    <collision>
      <origin xyz="0.26 0.22975 -0.21" rpy="0 0 0"/>
      <geometry>
        <mesh filename="package://sprinter_description/meshes/boggie_right.stl" scale="0.001 0.001 0.001"/>
      </geometry>
    </collision>
  </link>

  <link name="boggie_left">
    <inertial>
      <origin xyz="0.04608852267144553 0.05868381722034843 -0.0878295588540255" rpy="0 0 0"/>
      <mass value="9.26099437267114"/>
      <inertia ixx="0.043816" iyy="0.34178" izz="0.334085" ixy="-0.001419" iyz="0.011146" ixz="0.005146"/>
    </inertial>
    <visual>
      <origin xyz="0.26 -0.22975 -0.21" rpy="0 0 0"/>
      <geometry>
        <mesh filename="package://sprinter_description/meshes/boggie_left.stl" scale="0.001 0.001 0.001"/>
      </geometry>
      <material name="silver"/>
    </visual>
    <collision>
      <origin xyz="0.26 -0.22975 -0.21" rpy="0 0 0"/>
      <geometry>
        <mesh filename="package://sprinter_description/meshes/boggie_left.stl" scale="0.001 0.001 0.001"/>
      </geometry>
    </collision>
  </link>

  <link name="wheel_right_front">
    <inertial>
      <origin xyz="-2.2157215140428121e-07 0.049038331285879255 -5.319570878098423e-07" rpy="0 0 0"/>
      <mass value="16.784680388840883"/>
      <inertia ixx="0.065217" iyy="0.075835" izz="0.065217" ixy="-0.0" iyz="-0.0" ixz="-0.0"/>
    </inertial>
    <visual>
      <origin xyz="-0.42 0.38275 -0.09" rpy="0 0 0"/>
      <geometry>
        <mesh filename="package://sprinter_description/meshes/wheel_right_front.stl" scale="0.001 0.001 0.001"/>
      </geometry>
      <material name="silver"/>
    </visual>
    <collision>
      <origin xyz="-0.42 0.38275 -0.09" rpy="0 0 0"/>
      <geometry>
        <mesh filename="package://sprinter_description/meshes/wheel_right_front.stl" scale="0.001 0.001 0.001"/>
      </geometry>
    </collision>
  </link>

  <link name="wheel_right_middle">
    <inertial>
      <origin xyz="-2.441464656044445e-07 0.049038331285878034 -1.2471173249650747e-07" rpy="0 0 0"/>
      <mass value="16.784680388841224"/>
      <inertia ixx="0.065217" iyy="0.075835" izz="0.065217" ixy="-0.0" iyz="-0.0" ixz="-0.0"/>
    </inertial>
    <visual>
      <origin xyz="0.0 0.40375 -0.09" rpy="0 0 0"/>
      <geometry>
        <mesh filename="package://sprinter_description/meshes/wheel_right_middle.stl" scale="0.001 0.001 0.001"/>
      </geometry>
      <material name="silver"/>
    </visual>
    <collision>
      <origin xyz="0.0 0.40375 -0.09" rpy="0 0 0"/>
      <geometry>
        <mesh filename="package://sprinter_description/meshes/wheel_right_middle.stl" scale="0.001 0.001 0.001"/>
      </geometry>
    </collision>
  </link>

  <link name="wheel_right_rear">
    <inertial>
      <origin xyz="-2.4414526850202733e-07 0.04903833128586854 4.1045225383784523e-07" rpy="0 0 0"/>
      <mass value="16.78468038884136"/>
      <inertia ixx="0.065217" iyy="0.075835" izz="0.065217" ixy="-0.0" iyz="-0.0" ixz="-0.0"/>
    </inertial>
    <visual>
      <origin xyz="0.42 0.40375 -0.09" rpy="0 0 0"/>
      <geometry>
        <mesh filename="package://sprinter_description/meshes/wheel_right_rear.stl" scale="0.001 0.001 0.001"/>
      </geometry>
      <material name="silver"/>
    </visual>
    <collision>
      <origin xyz="0.42 0.40375 -0.09" rpy="0 0 0"/>
      <geometry>
        <mesh filename="package://sprinter_description/meshes/wheel_right_rear.stl" scale="0.001 0.001 0.001"/>
      </geometry>
    </collision>
  </link>

  <link name="wheel_left_front">
    <inertial>
      <origin xyz="-1.7782965933133e-08 -0.04903833128669849 -7.65968576066367e-08" rpy="0 0 0"/>
      <mass value="16.78468038884107"/>
      <inertia ixx="0.065217" iyy="0.075835" izz="0.065217" ixy="-0.0" iyz="0.0" ixz="0.0"/>
    </inertial>
    <visual>
      <origin xyz="-0.42 -0.38275 -0.09" rpy="0 0 0"/>
      <geometry>
        <mesh filename="package://sprinter_description/meshes/wheel_left_front.stl" scale="0.001 0.001 0.001"/>
      </geometry>
      <material name="silver"/>
    </visual>
    <collision>
      <origin xyz="-0.42 -0.38275 -0.09" rpy="0 0 0"/>
      <geometry>
        <mesh filename="package://sprinter_description/meshes/wheel_left_front.stl" scale="0.001 0.001 0.001"/>
      </geometry>
    </collision>
  </link>

  <link name="wheel_left_middle">
    <inertial>
      <origin xyz="1.038819750736053e-06 -0.049038331286717474 0.00010982563519425226" rpy="0 0 0"/>
      <mass value="16.784680388841238"/>
      <inertia ixx="0.065217" iyy="0.075835" izz="0.065217" ixy="-0.0" iyz="0.0" ixz="0.0"/>
    </inertial>
    <visual>
      <origin xyz="-0.0 -0.40375 -0.09" rpy="0 0 0"/>
      <geometry>
        <mesh filename="package://sprinter_description/meshes/wheel_left_middle.stl" scale="0.001 0.001 0.001"/>
      </geometry>
      <material name="silver"/>
    </visual>
    <collision>
      <origin xyz="-0.0 -0.40375 -0.09" rpy="0 0 0"/>
      <geometry>
        <mesh filename="package://sprinter_description/meshes/wheel_left_middle.stl" scale="0.001 0.001 0.001"/>
      </geometry>
    </collision>
  </link>

  <link name="wheel_left_rear">
    <inertial>
      <origin xyz="1.0388197915767172e-06 -0.04903833128671531 0.00010972160107960982" rpy="0 0 0"/>
      <mass value="16.7846803888409"/>
      <inertia ixx="0.065217" iyy="0.075835" izz="0.065217" ixy="-0.0" iyz="0.0" ixz="0.0"/>
    </inertial>
    <visual>
      <origin xyz="0.42 -0.40375 -0.09" rpy="0 0 0"/>
      <geometry>
        <mesh filename="package://sprinter_description/meshes/wheel_left_rear.stl" scale="0.001 0.001 0.001"/>
      </geometry>
      <material name="silver"/>
    </visual>
    <collision>
      <origin xyz="0.42 -0.40375 -0.09" rpy="0 0 0"/>
      <geometry>
        <mesh filename="package://sprinter_description/meshes/wheel_left_rear.stl" scale="0.001 0.001 0.001"/>
      </geometry>
    </collision>
  </link>

  <link name="body">
    <inertial>
      <origin xyz="-0.08748571926603223 0.002858790568392067 -0.009190179413522459" rpy="0 0 0"/>
      <mass value="37.61630562888167"/>
      <inertia ixx="0.853323" iyy="1.507235" izz="1.939307" ixy="-0.02383" iyz="-0.017735" ixz="-0.223821"/>
    </inertial>
    <visual>
      <origin xyz="0.0 0.0 -0.31" rpy="0 0 0"/>
      <geometry>
        <mesh filename="package://sprinter_description/meshes/body.stl" scale="0.001 0.001 0.001"/>
      </geometry>
      <material name="silver"/>
    </visual>
    <collision>
      <origin xyz="0.0 0.0 -0.31" rpy="0 0 0"/>
      <geometry>
        <mesh filename="package://sprinter_description/meshes/body.stl" scale="0.001 0.001 0.001"/>
      </geometry>
    </collision>
  </link>

  <link name="lens_Ylin">
    <inertial>
      <origin xyz="-0.19050492237401995 0.01911574728140262 0.050354275554037764" rpy="0 0 0"/>
      <mass value="8.115658394698128"/>
      <inertia ixx="0.588454" iyy="0.584795" izz="1.16382" ixy="0.014229" iyz="-0.000613" ixz="0.015923"/>
    </inertial>
    <visual>
      <origin xyz="-0.1445 0.020515 -0.453" rpy="0 0 0"/>
      <geometry>
        <mesh filename="package://sprinter_description/meshes/lens_Ylin.stl" scale="0.001 0.001 0.001"/>
      </geometry>
      <material name="silver"/>
    </visual>
    <collision>
      <origin xyz="-0.1445 0.020515 -0.453" rpy="0 0 0"/>
      <geometry>
        <mesh filename="package://sprinter_description/meshes/lens_Ylin.stl" scale="0.001 0.001 0.001"/>
      </geometry>
    </collision>
  </link>

  <link name="lens_Xlin">
    <inertial>
      <origin xyz="0.23595566779369742 0.13671241587093597 0.03333844333172431" rpy="0 0 0"/>
      <mass value="1.8074023885886255"/>
      <inertia ixx="0.123515" iyy="0.081004" izz="0.20416" ixy="-0.045751" iyz="-0.000469" ixz="-0.000589"/>
    </inertial>
    <visual>
      <origin xyz="0.2502 0.0 -0.49414" rpy="0 0 0"/>
      <geometry>
        <mesh filename="package://sprinter_description/meshes/lens_Xlin.stl" scale="0.001 0.001 0.001"/>
      </geometry>
      <material name="silver"/>
    </visual>
    <collision>
      <origin xyz="0.2502 0.0 -0.49414" rpy="0 0 0"/>
      <geometry>
        <mesh filename="package://sprinter_description/meshes/lens_Xlin.stl" scale="0.001 0.001 0.001"/>
      </geometry>
    </collision>
  </link>

  <link name="lens_Yrot">
    <inertial>
      <origin xyz="0.15610000473558938 -0.28034931010215036 0.01290803779832872" rpy="0 0 0"/>
      <mass value="1.6400641565943115"/>
      <inertia ixx="0.034387" iyy="0.070049" izz="0.103823" ixy="0.002102" iyz="0.00012" ixz="-0.002749"/>
    </inertial>
    <visual>
      <origin xyz="-0.144866 -0.270552 -0.528953" rpy="0 0 0"/>
      <geometry>
        <mesh filename="package://sprinter_description/meshes/lens_Yrot.stl" scale="0.001 0.001 0.001"/>
      </geometry>
      <material name="silver"/>
    </visual>
    <collision>
      <origin xyz="-0.144866 -0.270552 -0.528953" rpy="0 0 0"/>
      <geometry>
        <mesh filename="package://sprinter_description/meshes/lens_Yrot.stl" scale="0.001 0.001 0.001"/>
      </geometry>
    </collision>
  </link>

  <link name="lens_Xrot">
    <inertial>
      <origin xyz="-0.2533217422271652 7.584721687383723e-06 0.0013476837862036462" rpy="0 0 0"/>
      <mass value="6.552542872975625"/>
      <inertia ixx="0.149538" iyy="0.149827" izz="0.299329" ixy="0.0" iyz="0.000816" ixz="2e-06"/>
    </inertial>
    <visual>
      <origin xyz="-0.392366 8.1e-05 -0.552581" rpy="0 0 0"/>
      <geometry>
        <mesh filename="package://sprinter_description/meshes/lens_Xrot.stl" scale="0.001 0.001 0.001"/>
      </geometry>
      <material name="silver"/>
    </visual>
    <collision>
      <origin xyz="-0.392366 8.1e-05 -0.552581" rpy="0 0 0"/>
      <geometry>
        <mesh filename="package://sprinter_description/meshes/lens_Xrot.stl" scale="0.001 0.001 0.001"/>
      </geometry>
    </collision>
  </link>

  <!--  frame in the middle of the lens-->
  <link name="lens_middle">
    <inertial>
      <origin xyz="0.0 0.0 0.0" rpy="0 0 0"/>
      <mass value="0.0"/>
      <inertia ixx="0.0" iyy="0.0" izz="0.0" ixy="0.0" iyz="0.0" ixz="0.0"/>
    </inertial>
  </link>

  <link name="lens_focal">
    <inertial>
      <origin xyz="0.0 0.0 0.0" rpy="0 0 0"/>
      <mass value="0.0"/>
      <inertia ixx="0.0" iyy="0.0" izz="0.0" ixy="0.0" iyz="0.0" ixz="0.0"/>
    </inertial>
  </link>

  <link name="ref_print_space">
    <inertial>
      <origin xyz="0.0 0.0 0.0" rpy="0 0 0"/>
      <mass value="0.0"/>
      <inertia ixx="0.0" iyy="0.0" izz="0.0" ixy="0.0" iyz="0.0" ixz="0.0"/>
    </inertial>
  </link>

<!--  JOINTS  .......................................................................................................-->
  <joint name="Boggie_right" type="revolute">
    <origin xyz="-0.26 -0.22975 0.21" rpy="0 0 0"/>
    <parent link="base_link"/>
    <child link="boggie_right"/>
    <axis xyz="-0.0 1.0 0.0"/>
    <limit upper="0.523599" lower="-0.523599" effort="100" velocity="100"/>
  </joint>

  <joint name="Boggie_left" type="revolute">
    <origin xyz="-0.26 0.22975 0.21" rpy="0 0 0"/>
    <parent link="base_link"/>
    <child link="boggie_left"/>
    <axis xyz="0.0 1.0 0.0"/>
    <limit upper="0.523599" lower="-0.523599" effort="100" velocity="100"/>
  </joint>

  <joint name="Wheel_right_front" type="continuous">
    <origin xyz="0.42 -0.38275 0.09" rpy="0 0 0"/>
    <parent link="base_link"/>
    <child link="wheel_right_front"/>
    <axis xyz="0.0 1.0 0.0"/>
  </joint>

  <joint name="Wheel_right_middle" type="continuous">
    <origin xyz="0.26 -0.174 -0.12" rpy="0 0 0"/>
    <parent link="boggie_right"/>
    <child link="wheel_right_middle"/>
    <axis xyz="0.0 1.0 0.0"/>
  </joint>

  <joint name="Wheel_right_rear" type="continuous">
    <origin xyz="-0.16 -0.174 -0.12" rpy="0 0 0"/>
    <parent link="boggie_right"/>
    <child link="wheel_right_rear"/>
    <axis xyz="0.0 1.0 0.0"/>
  </joint>

  <joint name="Wheel_left_front" type="continuous">
    <origin xyz="0.42 0.38275 0.09" rpy="0 0 0"/>
    <parent link="base_link"/>
    <child link="wheel_left_front"/>
    <axis xyz="0.0 1.0 0.0"/>
  </joint>

  <joint name="Wheel_left_middle" type="continuous">
    <origin xyz="0.26 0.174 -0.12" rpy="0 0 0"/>
    <parent link="boggie_left"/>
    <child link="wheel_left_middle"/>
    <axis xyz="0.0 1.0 0.0"/>
  </joint>

  <joint name="Wheel_left_rear" type="continuous">
    <origin xyz="-0.16 0.174 -0.12" rpy="0 0 0"/>
    <parent link="boggie_left"/>
    <child link="wheel_left_rear"/>
    <axis xyz="0.0 1.0 0.0"/>
  </joint>

  <joint name="Body_pitch" type="revolute">
    <origin xyz="0.0 0.0 0.31" rpy="0 0 0"/>
    <parent link="base_link"/>
    <child link="body"/>
    <axis xyz="-0.0 1.0 0.0"/>
    <limit upper="0.523599" lower="-0.523599" effort="100" velocity="100"/>
  </joint>

  <joint name="Lens_Y_axis_trans" type="prismatic">
    <origin xyz="0.1445 -0.020515 0.143" rpy="0 0 0"/>
    <parent link="body"/>
    <child link="lens_Ylin"/>
    <axis xyz="0.0 1.0 0.0"/>
    <limit upper="0.15" lower="-0.12" effort="100" velocity="100"/>
  </joint>

  <joint name="Lens_X_axis_trans" type="prismatic">
    <origin xyz="-0.3947 0.020515 0.04114" rpy="0 0 0"/>
    <parent link="lens_Ylin"/>
    <child link="lens_Xlin"/>
    <axis xyz="1.0 -0.0 0.0"/>
    <limit upper="0.65" lower="0.0" effort="100" velocity="100"/>
  </joint>

  <joint name="Lens_Y_axis_rot" type="revolute">
    <origin xyz="0.395066 0.270552 0.034813" rpy="0 0 0"/>
    <parent link="lens_Xlin"/>
    <child link="lens_Yrot"/>
    <axis xyz="0.0 0.999999 0.001376"/>
    <limit upper="0.698132" lower="-0.698132" effort="100" velocity="100"/>
  </joint>

  <joint name="Lens_X_axis_rot" type="revolute">
    <origin xyz="0.2475 -0.270633 0.023628" rpy="0 0 0"/>
    <parent link="lens_Yrot"/>
    <child link="lens_Xrot"/>
    <axis xyz="1.0 -0.0 0.0"/>
    <limit upper="1.2" lower="-1.2" effort="100" velocity="100"/>
  </joint>

  <!--middle frame joint-->
  <joint name="lens_middle_joint" type="fixed">
    <origin xyz="-0.2535  0.0 0.0" rpy="0 0 0"/>
    <parent link="lens_Xrot"/>
    <child link="lens_middle"/>
  </joint>

  <!--focal work frame joint-->
  <joint name="lens_focal_joint" type="fixed">
    <origin rpy="0 0 0" xyz="0.0 0.0 -0.55" />
            <!-- z: ohniskova vzdialenost -->
    <parent link="lens_middle"/>
    <child link="lens_focal"/>
  </joint>

  <!--focal static frame joint-->
  <joint name="ref_print_space_joint" type="fixed">
    <origin rpy="0 0 0" xyz="0.753764 0.0 -0.0" />
            <!-- z: -55cm - ohniskova vzdialenost = 0cm nad rovinou zeme-->
            <!-- x: 0.753764 je pri 0.615m vysunuti sosovky v x (HOME) ... pod lens_middle frame-->
    <parent link="base_link"/>
    <child link="ref_print_space"/>
  </joint>

</robot>
